<mujoco model="j2s6s300">
    <compiler angle="radian" meshdir="common/kinova_meshes/" balanceinertia="true" />
  <option integrator="RK4" solver="PGS" timestep="0.001" gravity="0 0 0" iterations="50"/>

    <size njmax="500" nconmax="100" />
    <asset>
        <mesh name="base" file="base.STL" />
        <mesh name="shoulder" file="shoulder.STL" />
        <mesh name="arm" file="arm.STL" />
        <mesh name="forearm" file="forearm.STL" />
        <mesh name="wrist_spherical_1" file="wrist_spherical_1.STL" />
        <mesh name="wrist_spherical_2" file="wrist_spherical_2.STL" />
        <mesh name="hand_3finger" file="hand_3finger.STL" />
        <mesh name="finger_proximal" file="finger_proximal.STL" />
        <mesh name="finger_distal" file="finger_distal.STL" />

<texture name="groundplane" type="2d" builtin="checker" rgb1=".25 .26 .25"
      rgb2=".22 .22 .22" width="100" height="100" mark="none" markrgb=".8 .8 .8"/>
    </asset>

 <default>
    <geom contype='1' conaffinity='1' condim='3' margin="0.001" />

    <joint limited="false" damping="0" armature=".01"/>

    <default class ="vizNcoll">
      <geom material="MatViz" type="mesh" condim="3" contype="1" conaffinity="1" margin="0.001"/>
      <joint pos="0 0 0" type="hinge"/>
    </default>
    <default class ="ground">
      <geom type="plane" margin="0.001" contype="1" />
    </default>
  </default>
    <worldbody>
 <light cutoff="200" diffuse="1.2 1.2 1.2" dir="-0 0 -1.3" directional="true" exponent="1" pos="0 0 1.3" specular=".1 .1 .1"/>

     <camera name="view1" pos="0 0 2.0" zaxis="0 0 1" fovy="45" ipd="0.068"/>
    <camera name="view2" pos="1.0 0.7 0.3" xyaxes="-1 1 0 0 0 1" fovy="45" ipd="0.068"/>

	
 <geom name="ground" class="ground" type='plane' pos="0 0 0" rgba="0.19 0.30 0.23 1" size="2 2 1"/>
        <geom type="mesh" rgba="0.17 0.17 0.17 1" mesh="base" />

        <body name="jaco_link_1" pos="0 0 0.15675" quat="0 0 1 0">
            <inertial pos="0 -0.002 -0.0605" mass="0.7477" diaginertia="0.00152032 0.00152032 0.00059816" />
            <joint name="jaco_joint_1" pos="0 0 0" axis="0 0 1" limited="true" range="-6.28319 6.28319" />
            <geom type="mesh" rgba="0.17 0.17 0.17 1" mesh="shoulder" />
            <body name="jaco_link_2" pos="0 0.0016 -0.11875" quat="0 0 -0.707107 0.707107">
                <inertial pos="0 -0.2065 -0.01" quat="0.707107 0.707107 0 0" mass="0.99" diaginertia="0.0105022 0.0105022 0.000792" />
                <joint name="jaco_joint_2" pos="0 0 0" axis="0 0 1" limited="true" range="0.820305 5.46288" />
                <geom type="mesh" rgba="0.17 0.17 0.17 1" mesh="arm" />
                <body name="jaco_link_3" pos="0 -0.41 0" quat="0 0 1 0">
                    <inertial pos="0 0.081 -0.0086" quat="0.707107 0.707107 0 0" mass="0.6763" diaginertia="0.00142022 0.00142022 0.000304335" />
                    <joint name="jaco_joint_3" pos="0 0 0" axis="0 0 1" limited="true" range="0.331613 5.95157" />
                    <geom type="mesh" rgba="0.17 0.17 0.17 1" mesh="forearm" />
                    <body name="jaco_link_4" pos="0 0.2073 -0.0114" quat="0 0 -0.707107 0.707107">
                        <inertial pos="0 0.00288489 -0.0541933" mass="0.463" diaginertia="0.000432132 0.000432132 9.26e-05" />
                        <joint name="jaco_joint_4" pos="0 0 0" axis="0 0 1" limited="true" range="-6.28319 6.28319" />
                        <geom type="mesh" rgba="0.17 0.17 0.17 1" mesh="wrist_spherical_1" />
                        <body name="jaco_link_5" pos="0 0 -0.10375" quat="0 0 0.707107 0.707107">
                            <inertial pos="0 0.0497209 -0.00285628" quat="0.707107 0.707107 0 0" mass="0.463" diaginertia="0.000432132 0.000432132 9.26e-05" />
                            <joint name="jaco_joint_5" pos="0 0 0" axis="0 0 1" limited="true" range="0.523599 5.75959" />
                            <geom type="mesh" rgba="0.17 0.17 0.17 1" mesh="wrist_spherical_2" />
                            <body name="jaco_link_6" pos="0 0.10375 0" quat="0 0 -0.707107 0.707107">
                                <inertial pos="0 0 -0.06" quat="0.5 0.5 -0.5 0.5" mass="0.99" diaginertia="0.0005816 0.000345324 0.000345324" />
                                <joint name="jaco_joint_6" pos="0 0 0" axis="0 0 1" limited="true" range="-6.28319 6.28319" />
                                <geom type="mesh" rgba="0.73 0.73 0.73 1" mesh="hand_3finger" />
                                <body name="jaco_link_finger_1" pos="0.00279 0.03126 -0.11467" quat="0.379408 -0.662973 -0.245899 0.596699">
                                    <inertial pos="0.022 0 0" mass="0.01" diaginertia="7.89997e-07 7.89997e-07 8e-08" />
                                    <joint name="jaco_joint_finger_1" pos="0 0 0" axis="0 0 1" limited="true" range="0 1.51" />
                                    <geom type="mesh" rgba="0.17 0.17 0.17 1" mesh="finger_proximal" />
                                    <body name="jaco_link_finger_tip_1" pos="0.044 -0.003 0">
                                        <inertial pos="0.022 0 0" mass="0.01" diaginertia="7.89997e-07 7.89997e-07 8e-08" />
                                        <joint name="jaco_joint_finger_tip_1" pos="0 0 0" axis="0 0 1" limited="true" range="0 2" />
                                        <geom type="mesh" rgba="0.73 0.73 0.73 1" mesh="finger_distal" />
                                    </body>
                                </body>
                                <body name="jaco_link_finger_2" pos="0.02226 -0.02707 -0.11482" quat="0.659653 -0.37146 0.601679 -0.254671">
                                    <inertial pos="0.022 0 0" mass="0.01" diaginertia="7.89997e-07 7.89997e-07 8e-08" />
                                    <joint name="jaco_joint_finger_2" pos="0 0 0" axis="0 0 1" limited="true" range="0 1.51" />
                                    <geom type="mesh" rgba="0.17 0.17 0.17 1" mesh="finger_proximal" />
                                    <body name="jaco_link_finger_tip_2" pos="0.044 -0.003 0">
                                        <inertial pos="0.022 0 0" mass="0.01" diaginertia="7.89997e-07 7.89997e-07 8e-08" />
                                        <joint name="jaco_joint_finger_tip_2" pos="0 0 0" axis="0 0 1" limited="true" range="0 2" />
                                        <geom type="mesh" rgba="0.73 0.73 0.73 1" mesh="finger_distal" />
                                    </body>
                                </body>
                                <body name="jaco_link_finger_3" pos="-0.02226 -0.02707 -0.11482" quat="0.601679 -0.254671 0.659653 -0.37146">
                                    <inertial pos="0.022 0 0" mass="0.01" diaginertia="7.89997e-07 7.89997e-07 8e-08" />
                                    <joint name="jaco_joint_finger_3" pos="0 0 0" axis="0 0 1" limited="true" range="0 1.51" />
                                    <geom type="mesh" rgba="0.17 0.17 0.17 1" mesh="finger_proximal" />
                                    <body name="jaco_link_finger_tip_3" pos="0.044 -0.003 0">
                                        <inertial pos="0.022 0 0" mass="0.01" diaginertia="7.89997e-07 7.89997e-07 8e-08" />
                                        <joint name="jaco_joint_finger_tip_3" pos="0 0 0" axis="0 0 1" limited="true" range="0 2" />
                                        <geom type="mesh" rgba="0.73 0.73 0.73 1" mesh="finger_distal" />
                                    </body>
                                </body>
                            </body>
                        </body>
                    </body>
                </body>
            </body>
        </body>
    </worldbody>


  <!--  ================= Velocity actuators ================= /-->
  <actuator>
    <velocity joint='jaco_joint_1'  name='jaco_joint_1' kv="25" ctrlrange="-1 1" ctrllimited="true"/>
    <velocity joint='jaco_joint_2'  name='jaco_joint_2' kv="25" ctrlrange="-1 1" ctrllimited="true"/>
    <velocity joint='jaco_joint_3'  name='jaco_joint_3' kv="25" ctrlrange="-1 1" ctrllimited="true"/>
    <velocity joint='jaco_joint_4'  name='jaco_joint_4' kv="25" ctrlrange="-1 1" ctrllimited="true"/>
    <velocity joint='jaco_joint_5'  name='jaco_joint_5' kv="25" ctrlrange="-1 1" ctrllimited="true"/>
    <velocity joint='jaco_joint_6'  name='jaco_joint_6' kv="25" ctrlrange="-1 1" ctrllimited="true"/>
    <velocity joint='jaco_joint_finger_1'  name='jaco_joint_finger_1' kv="25" ctrlrange="-1 1" ctrllimited="true"/>
    <velocity joint='jaco_joint_finger_2'  name='jaco_joint_finger_2' kv="25" ctrlrange="-1 1" ctrllimited="true"/>
    <velocity joint='jaco_joint_finger_3'  name='jaco_joint_finger_3' kv="25" ctrlrange="-1 1" ctrllimited="true"/>
    <velocity joint='jaco_joint_finger_tip_1'  name='jaco_joint_finger_tip_1' kv="25" ctrlrange="-1 1" ctrllimited="true"/>
    <velocity joint='jaco_joint_finger_tip_2'  name='jaco_joint_finger_tip_2' kv="25" ctrlrange="-1 1" ctrllimited="true"/>
    <velocity joint='jaco_joint_finger_tip_3'  name='jaco_joint_finger_tip_3' kv="25" ctrlrange="-1 1" ctrllimited="true"/>
  </actuator>
 
</mujoco>
